Workbook

Sheet Summary
A1: Semrush Keyword Strategy - fridgerepairblacktown.com.au
A2: Prepared 16 Oct 2026 | Source: Semrush (Australia database, desktop) | Filters: KD 0-20%, intent Commercial / Transactional, repair-related terms, volume 50+
A4: KEY NUMBERS
A5: Target keywords (in scope) | B5: =COUNTIFS(Keywords!H2:H140,"<>P4 - Optional") -> 126
A6: Combined monthly search volume (in scope) | B6: =SUMIFS(Keywords!D2:D140,Keywords!H2:H140,"<>P4 - Optional") -> 27010
A7: Average keyword difficulty (in scope) | B7: =ROUND(AVERAGEIFS(Keywords!E2:E140,Keywords!H2:H140,"<>P4 - Optional"),1) -> 10.7
A8: Keywords on EXISTING pages | B8: =COUNTIFS(Keywords!L2:L140,"EXISTING PAGE",Keywords!H2:H140,"<>P4 - Optional") -> 60
A9: Keywords needing NEW pages | B9: =COUNTIFS(Keywords!L2:L140,"NEW PAGE",Keywords!H2:H140,"<>P4 - Optional") -> 66
A10: Existing pages to optimise | B10: =COUNTIF('Page Map'!C2:C66,"EXISTING - optimise") -> 7
A11: New pages to create (service, brand, suburb + 3 support pages) | B11: =COUNTIF('Page Map'!C2:C66,"NEW") -> 58
A12: Optional low-relevance keywords (inner west / eastern suburbs, P4) | B12: =COUNTIF(Keywords!H2:H140,"P4 - Optional") -> 13
A13: New finds not in the previous plan | B13: =COUNTIF(Keywords!N2:N140,"No - new find") -> 112
A14: Suburb pages planned (Tier 1 / 2 / 3 / extended) | B14: =COUNTIF('Page Map'!D2:D66,"Suburb")+COUNTIF('Page Map'!D2:D66,"Commercial zone") -> 40
A16: WHAT THE SEMRUSH DATA SAYS
A17: 1. Demand is real and difficulty is low: the in-scope list averages KD ~11 and the best terms (fridge repairs near me 2,400/mo KD 12; fridge repairs 1,600 KD 16; fridge repair 1,300 KD 14) are all inside KD 0-20.
A18: 2. Brand pages are the largest untapped pool. Fisher & Paykel alone has ~3,600 searches/mo at KD 4-17, Westinghouse ~840, LG ~870, Samsung ~400. None of these pages exist on the site yet.
A19: 3. Commercial refrigeration has the highest lead value: CPC $6-$13 on terms like "commercial refrigeration repair" (720/mo, KD 14), "commercial freezer repair" (590, KD 10) and "refrigerator commercial repair" (CPC $13.59). The page exists but needs optimising.
A20: 4. Two new commercial clusters are missing entirely: Ice machine repair (8 keywords, KD 3-9, ~1,100/mo) and Coolroom / cold room repair (5 keywords, ~520/mo, CPC up to $15).
A21: 5. Blacktown itself is small (fridge repairs blacktown 110/mo KD 6; fridge repair blacktown 50/mo KD 5), so the homepage must also capture the big generic and "near me" terms, backed by Google Business Profile.
A22: 6. SUBURB PAGES - decision: YES, build them, as a supporting layer. Evidence: masterfridgerepairs.com.au has 80 suburb pages and fastfridgerepairs.com.au has 133 (out of 111 / 191 URLs); the #1 organic result for "fridge repairs blacktown" is a dedicated suburb page. But Semrush shows each suburb page gets only 0-19 visits/month (homepage = 69% / 50% of their traffic; all suburb pages together ~11% / ~22%). So: low volume, low difficulty (KD 4-6), cheap wins - not the main traffic source.
A23: 7. Suburb demand: measurable volume exists for Penrith ~280 (3 variants), Smithfield 170, Parramatta 140, Castle Hill 140, Richmond 90, Glenwood 70, Rouse Hill 50, St Marys 50. Most Blacktown-area suburbs (Doonside, Marayong, Quakers Hill, Mount Druitt, Seven Hills...) are below Semrush reporting level (<10/mo each) - they are included for local relevance, Map Pack proximity and because 12 of your suburbs have NO competitor page at all.
A24: 8. Competitors are weak: local players have Domain Authority 8-17 and 150-260 referring domains, only a few have a dedicated Blacktown page, and none visibly cover brands, coolroom or ice machines locally.
A25: 9. Search intent note: Semrush labels many "fridge repair [suburb]" terms Commercial (comparison / hire intent). Treat them as lead-gen pages with a phone number and booking form above the fold.
A27: HOW TO USE THIS FILE
A28: • Keywords tab: every keyword with volume, KD, CPC, intent, priority, and the page it belongs to (filter by "Page Status" to see EXISTING vs NEW).
... A40: • No Google Search Console, keyword rank-tracking or on-page crawl data was available - the site audit comes from the sitemap and homepage text only.

Sheet Page Map
A1: # | B1: Publish Week | C1: Page Status | D1: Page Type | E1: URL | F1: Primary Keyword | G1: Primary Vol | H1: Primary KD % | I1: Keywords Mapped | J1: Total Volume (excl. P4) | K1: Avg KD % | L1: Avg CPC (USD) | M1: Priority | N1: Title Tag (<=60) | O1: Title Len | P1: H1 | Q1: Word Count | R1: Secondary Keywords (top 8 by volume) | S1: In previous plan? | T1: Notes
A2: 1 | B2: Week 1 (19 - 25 Oct) | C2: EXISTING - optimise | D2: Homepage | E2: / | F2: fridge repairs near me | G2: 2400 | H2: 12 | I2: =COUNTIF(Keywords!$K$2:$K$140,E2) -> 16 | J2: =SUMIFS(Keywords!$D$2:$D$140,Keywords!$K$2:$K$140,E2,Keywords!$H$2:$H$140,"<>P4 - Optional") -> 7340 | K2: =IFERROR(ROUND(AVERAGEIFS(Keywords!$E$2:$E$140,Keywords!$K$2:$K$140,E2,Keywords!$H$2:$H$140,"<>P4 - Optional"),1),"n/a") -> 11.6 | L2: =IFERROR(ROUND(AVERAGEIFS(Keywords!$F$2:$F$140,Keywords!$K$2:$K$140,E2,Keywords!$H$2:$H$140,"<>P4 - Optional"),2),"n/a") -> 1.98 | M2: P1 | N2: Fridge Repairs Blacktown | Same-Day Local Technicians | O2: =LEN(N2) -> 53 | P2: Fridge Repairs Blacktown | Q2: 1,800-2,200 | R2: fridge repairs, fridge repair, refrigerator mechanic near me, fridge technician near me, fridge mechanic, technician for fridge, fridge repair technician, fridge repairs blacktown (+7 more in Keywords tab) | S2: Yes (planned) | T2: Local money page. Add phone + click-to-call in first screen; link every section to its own page. Needs real Google reviews + NAP.
A3: 2 | B3: Week 1 (19 - 25 Oct) | C3: EXISTING - optimise | D3: Service | E3: /commercial-fridge-repair-blacktown/ | F3: commercial refrigeration repair | G3: 720 | H3: 14 | I3: =COUNTIF(Keywords!$K$2:$K$140,E3) -> 17 | J3: =SUMIFS(Keywords!$D$2:$D$140,Keywords!$K$2:$K$140,E3,Keywords!$H$2:$H$140,"<>P4 - Optional") -> 4170 | K3: =IFERROR(ROUND(AVERAGEIFS(Keywords!$E$2:$E$140,Keywords!$K$2:$K$140,E3,Keywords!$H$2:$H$140,"<>P4 - Optional"),1),"n/a") -> 12.3 | L3: =IFERROR(ROUND(AVERAGEIFS(Keywords!$F$2:$F$140,Keywords!$K$2:$K$140,E3,Keywords!$H$2:$H$140,"<>P4 - Optional"),2),"n/a") -> 7.91 | M3: P1 | N3: Commercial Fridge Repairs Blacktown | 24/7 Service | O3: =LEN(N3) -> 50 | P3: Commercial Fridge & Refrigeration Repairs in Blacktown | Q3: 1,300-1,600 | R3: commercial freezer repair, commercial fridge repair, commercial refrigeration repairs, commercial refrigeration services, refrigerator commercial repair, commercial fridge service, commercial freezer repairs, commercial refrigeration repair near me (+8 more in Keywords tab) | S3: Yes (planned) | T3: Highest CPC cluster ($6-$13) = highest commercial value. Add industries, equipment types, SLA / response time, maintenance plans.
A4: 3 | B4: Week 1 (19 - 25 Oct) | C4: EXISTING - optimise | D4: Service | E4: /residential-fridge-repair/ | F4: repair refrigerator service | G4: 720 | H4: 13 | I4: =COUNTIF(Keywords!$K$2:$K$140,E4) -> 19 | J4: =SUMIFS(Keywords!$D$2:$D$140,Keywords!$K$2:$K$140,E4,Keywords!$H$2:$H$140,"<>P4 - Optional") -> 4160 | K4: =IFERROR(ROUND(AVERAGEIFS(Keywords!$E$2:$E$140,Keywords!$K$2:$K$140,E4,Keywords!$H$2:$H$140,"<>P4 - Optional"),1),"n/a") -> 13.4 | L4: =IFERROR(ROUND(AVERAGEIFS(Keywords!$F$2:$F$140,Keywords!$K$2:$K$140,E4,Keywords!$H$2:$H$140,"<>P4 - Optional"),2),"n/a") -> 2.51 | M4: P1 | N4: Residential Fridge Repair Blacktown | All Brands | O4: =LEN(N4) -> 48 | P4: Residential Fridge Repair in Blacktown | Q4: 1,100-1,400 | R4: fridge service and repair, refrigerator repair service, refrigeration service, refridgerator repairs, refigerator repair, repair fridges, refrigerator freezer repair, refrigerator refrigerator repair (+10 more in Keywords tab) | S4: Yes (planned) | T4: Takes the generic "fridge service / repair service" terms. Keep Blacktown in H1 and first paragraph.
A5: 4 | B5: Week 1 (19 - 25 Oct) | C5: NEW | D5: Brand | E5: /fisher-paykel-fridge-repair/ | F5: fisher and paykel fridge repairs | G5: 1000 | H5: 12 | I5: =COUNTIF(Keywords!$K$2:$K$140,E5) -> 11 | J5: =SUMIFS(Keywords!$D$2:$D$140,Keywords!$K$2:$K$140,E5,Keywords!$H$2:$H$140,"<>P4 - Optional") -> 3640 | K5: =IFERROR(ROUND(AVERAGEIFS(Keywords!$E$2:$E$140,Keywords!$K$2:$K$140,E5,Keywords!$H$2:$H$140,"<>P4 - Optional"),1),"n/a") -> 13.2 | L5: =IFERROR(ROUND(AVERAGEIFS(Keywords!$F$2:$F$140,Keywords!$K$2:$K$140,E5,Keywords!$H$2:$H$140,"<>P4 - Optional"),2),"n/a") -> 1.54 | M5: P1 | N5: Fisher & Paykel Fridge Repairs Blacktown | Local Techs | O5: =LEN(N5) -> 54 | P5: Fisher & Paykel Fridge Repair in Blacktown | Q5: 1,000-1,300 | R5: fisher & paykel fridge repairs, fisher and paykel refrigerator repair, fisher and paykel appliance repairs, fisher and paykel repair service near me, fisher and paykel service repair, fisher paykel appliance repair near me, fisher paykel repair near me, fisher and paykel repairs near me (+2 more in Keywords tab) | S5: No - new find | T5: BIGGEST single opportunity: ~3,600 combined monthly searches at KD 4-17. Do NOT claim "authorised service agent" unless true. Add real model numbers / jobs.
A6: 5 | B6: Week 1 (19 - 25 Oct) | C6: EXISTING - optimise | D6: Service | E6: /emergency-fridge-repair/ | F6: emergency commercial refrigeration repair | G6: 210 | H6: 5 | I6: =COUNTIF(Keywords!$K$2:$K$140,E6) -> 4 | J6: =SUMIFS(Keywords!$D$2:$D$140,Keywords!$K$2:$K$140,E6,Keywords!$H$2:$H$140,"<>P4 - Optional") -> 380 | K6: =IFERROR(ROUND(AVERAGEIFS(Keywords!$E$2:$E$140,Keywords!$K$2:$K$140,E6,Keywords!$H$2:$H$140,"<>P4 - Optional"),1),"n/a") -> 11.5 | L6: =IFERROR(ROUND(AVERAGEIFS(Keywords!$F$2:$F$140,Keywords!$K$2:$K$140,E6,Keywords!$H$2:$H$140,"<>P4 - Optional"),2),"n/a") -> 1.85 | M6: P1 | N6: Emergency Fridge Repair Blacktown | 24/7 Call-Out | O6: =LEN(N6) -> 49 | P6: 24/7 Emergency Fridge Repair in Blacktown | Q6: 1,000-1,300 | R6: same day fridge repair, urgent fridge repair, emergency refrigerator repair | S6: Yes (planned) | T6: Add commercial emergency (coolroom / display) section to cover "emergency commercial refrigeration repair". Confirm after-hours rates before publishing.
A7: 6 | B7: Week 2 (26 Oct - 1 Nov) | C7: NEW | D7: Service | E7: /ice-machine-repair/ | F7: refrigerator ice machine repair | G7: 320 | H7: 6 | I7: =COUNTIF(Keywords!$K$2:$K$140,E7) -> 8 | J7: =SUMIFS(Keywords!$D$2:$D$140,Keywords!$K$2:$K$140,E7,Keywords!$H$2:$H$140,"<>P4 - Optional") -> 1120 | K7: =IFERROR(ROUND(AVERAGEIFS(Keywords!$E$2:$E$140,Keywords!$K$2:$K$140,E7,Keywords!$H$2:$H$140,"<>P4 - Optional"),1),"n/a") -> 5.6 | L7: =IFERROR(ROUND(AVERAGEIFS(Keywords!$F$2:$F$140,Keywords!$K$2:$K$140,E7,Keywords!$H$2:$H$140,"<>P4 - Optional"),2),"n/a") -> 3.23 | M7: P1 | N7: Ice Machine Repair Blacktown & Western Sydney | O7: =LEN(N7) -> 45 | P7: Ice Machine Repair & Service in Blacktown | Q7: 1,100-1,400 | R7: ice machine repair, ice machine repairs, ice machine service, ice machine repair service, ice maker repair service, ice maker machine repair, restaurant ice machine repair near me | S7: Yes (planned) | T7: Big untapped cluster: 8 keywords, KD 3-9. Cafes / restaurants / pubs. Few local competitors have a dedicated page.
A8: 7 | B8: Week 2 (26 Oct - 1 Nov) | C8: NEW | D8: Brand | E8: /westinghouse-fridge-repair/ | F8: westinghouse refrigerator repairs | G8: 590 | H8: 13 | I8: =COUNTIF(Keywords!$K$2:$K$140,E8) -> 3 | J8: =SUMIFS(Keywords!$D$2:$D$140,Keywords!$K$2:$K$140,E8,Keywords!$H$2:$H$140,"<>P4 - Optional") -> 840 | K8: =IFERROR(ROUND(AVERAGEIFS(Keywords!$E$2:$E$140,Keywords!$K$2:$K$140,E8,Keywords!$H$2:$H$140,"<>P4 - Optional"),1),"n/a") -> 11.3 | L8: =IFERROR(ROUND(AVERAGEIFS(Keywords!$F$2:$F$140,Keywords!$K$2:$K$140,E8,Keywords!$H$2:$H$140,"<>P4 - Optional"),2),"n/a") -> 1.97 | M8: P1 | N8: Westinghouse Fridge Repairs Blacktown | Same Day | O8: =LEN(N8) -> 48 | P8: Westinghouse Fridge Repair in Blacktown | Q8: 900-1,200 | R8: westinghouse fridge repairs near me, westinghouse repairs near me | S8: Yes (planned) | T8: Westinghouse refrigerator repairs = 590/mo, KD 13.
A9: 8 | B9: Week 2 (26 Oct - 1 Nov) | C9: EXISTING - optimise | D9: Service | E9: /freezer-repair-blacktown/ | F9: freezer repair | G9: 480 | H9: 7 | I9: =COUNTIF(Keywords!$K$2:$K$140,E9) -> 3 | J9: =SUMIFS(Keywords!$D$2:$D$140,Keywords!$K$2:$K$140,E9,Keywords!$H$2:$H$140,"<>P4 - Optional") -> 660 | K9: =IFERROR(ROUND(AVERAGEIFS(Keywords!$E$2:$E$140,Keywords!$K$2:$K$140,E9,Keywords!$H$2:$H$140,"<>P4 - Optional"),1),"n/a") -> 6.7 | L9: =IFERROR(ROUND(AVERAGEIFS(Keywords!$F$2:$F$140,Keywords!$K$2:$K$140,E9,Keywords!$H$2:$H$140,"<>P4 - Optional"),2),"n/a") -> 1.45 | M9: P1 | N9: Freezer Repair Blacktown | Chest & Upright Freezers | O9: =LEN(N9) -> 51 | P9: Freezer Repair in Blacktown | Q9: 900-1,200 | R9: freeze repair service, freeze repair near me | S9: Yes (planned) | T9: Also catches "freeze repair" misspellings. Mention chest, upright, commercial freezers.
A10: 9 | B10: Week 2 (26 Oct - 1 Nov) | C10: NEW | D10: Service | E10: /coolroom-repair/ | F10: coolroom repairs near me | G10: 170 | H10: 20 | I10: =COUNTIF(Keywords!$K$2:$K$140,E10) -> 5 | J10: =SUMIFS(Keywords!$D$2:$D$140,Keywords!$K$2:$K$140,E10,Keywords!$H$2:$H$140,"<>P4 - Optional") -> 520 | K10: =IFERROR(ROUND(AVERAGEIFS(Keywords!$E$2:$E$140,Keywords!$K$2:$K$140,E10,Keywords!$H$2:$H$140,"<>P4 - Optional"),1),"n/a") -> 10.8 | L10: =IFERROR(ROUND(AVERAGEIFS(Keywords!$F$2:$F$140,Keywords!$K$2:$K$140,E10,Keywords!$H$2:$H$140,"<>P4 - Optional"),2),"n/a") -> 8.78 | M10: P1 | N10: Coolroom Repairs Blacktown | Cold Room Technicians | O10: =LEN(N10) -> 50 | P10: Coolroom & Cold Room Repairs in Blacktown | Q10: 1,100-1,400 | R10: cool room repair, commercial cool room repairs, coolroom repair, cold room repairs | S10: Yes (planned) | T10: Footer already mentions coolroom repairs but links to #services - no real page yet. CPC up to $15 = very high lead value.
A11: 10 | B11: Week 2 (26 Oct - 1 Nov) | C11: EXISTING - optimise | D11: Service | E11: /fridge-regas/ | F11: refrigerator regas | G11: 140 | H11: 7 | I11: =COUNTIF(Keywords!$K$2:$K$140,E11) -> 1 | J11: =SUMIFS(Keywords!$D$2:$D$140,Keywords!$K$2:$K$140,E11,Keywords!$H$2:$H$140,"<>P4 - Optional") -> 140 | K11: =IFERROR(ROUND(AVERAGEIFS(Keywords!$E$2:$E$140,Keywords!$K$2:$K$140,E11,Keywords!$H$2:$H$140,"<>P4 - Optional"),1),"n/a") -> 7 | L11: =IFERROR(ROUND(AVERAGEIFS(Keywords!$F$2:$F$140,Keywords!$K$2:$K$140,E11,Keywords!$H$2:$H$140,"<>P4 - Optional"),2),"n/a") -> 1.53 | M11: P1 | N11: Fridge Regas Blacktown | Gas Leak Repair & Recharge | O11: =LEN(N11) -> 51 | P11: Fridge Regas & Gas Leak Repair in Blacktown | Q11: 900-1,200 | R11: - | S11: Yes (planned) | T11: Low KD (7). Explain gas type, leak test, regas vs compressor so it also feeds the compressor page.
A12: 11 | B12: Week 2 (26 Oct - 1 Nov) | C12: NEW | D12: Suburb | E12: /fridge-repair-penrith/ | F12: fridge repairs penrith | G12: 140 | H12: 7 | I12: =COUNTIF(Keywords!$K$2:$K$140,E12) -> 3 | J12: =SUMIFS(Keywords!$D$2:$D$140,Keywords!$K$2:$K$140,E12,Keywords!$H$2:$H$140,"<>P4 - Optional") -> 280 | K12: =IFERROR(ROUND(AVERAGEIFS(Keywords!$E$2:$E$140,Keywords!$K$2:$K$140,E12,Keywords!$H$2:$H$140,"<>P4 - Optional"),1),"n/a") -> 6.7 | L12: =IFERROR(ROUND(AVERAGEIFS(Keywords!$F$2:$F$140,Keywords!$K$2:$K$140,E12,Keywords!$H$2:$H$140,"<>P4 - Optional"),2),"n/a") -> 1.5 | M12: P2 | N12: Fridge Repair Penrith | Local Technicians, Same Day | O12: =LEN(N12) -> 51 | P12: Fridge Repair in Penrith | Q12: 600-800 | R12: refrigerator repairs penrith, fridge repair penrith | S12: No - new find | T12: Tier 1: Semrush demand and/or both competitors cover it. Both Master and Fast have a page. See Suburb Pages tab for the unique-content checklist. Confirm you service this suburb before publishing.
A13: 12 | B13: Week 2 (26 Oct - 1 Nov) | C13: NEW | D13: Suburb | E13: /fridge-repair-smithfield/ | F13: fridge repairs smithfield | G13: 170 | H13: 5 | I13: =COUNTIF(Keywords!$K$2:$K$140,E13) -> 1 | J13: =SUMIFS(Keywords!$D$2:$D$140,Keywords!$K$2:$K$140,E13,Keywords!$H$2:$H$140,"<>P4 - Optional") -> 170 | K13: =IFERROR(ROUND(AVERAGEIFS(Keywords!$E$2:$E$140,Keywords!$K$2:$K$140,E13,Keywords!$H$2:$H$140,"<>P4 - Optional"),1),"n/a") -> 5 | L13: =IFERROR(ROUND(AVERAGEIFS(Keywords!$F$2:$F$140,Keywords!$K$2:$K$140,E13,Keywords!$H$2:$H$140,"<>P4 - Optional"),2),"n/a") -> 0 | M13: P2 | N13: Fridge Repair Smithfield | Local Technicians, Same Day | O13: =LEN(N13) -> 54 | P13: Fridge Repair in Smithfield | Q13: 600-800 | R13: - | S13: No - new find | T13: Tier 1: Semrush demand and/or both competitors cover it. Both Master and Fast have a page. See Suburb Pages tab for the unique-content checklist. Confirm you service this suburb before publishing.
... A22: 21 | B22: Week 3 (2 - 8 Nov) | C22: NEW | D22: Suburb | E22: /fridge-repair-st-marys/ | F22: fridge repairs st marys | G22: 50 | H22: 6 | I22: =COUNTIF(Keywords!$K$2:$K$140,E22) -> 1 | J22: =SUMIFS(Keywords!$D$2:$D$140,Keywords!$K$2:$K$140,E22,Keywords!$H$2:$H$140,"<>P4 - Optional") -> 50 | K22: =IFERROR(ROUND(AVERAGEIFS(Keywords!$E$2:$E$140,Keywords!$K$2:$K$140,E22,Keywords!$H$2:$H$140,"<>P4 - Optional"),1),"n/a") -> 6 | L22: =IFERROR(ROUND(AVERAGEIFS(Keywords!$F$2:$F$140,Keywords!$K$2:$K$140,E22,Keywords!$H$2:$H$140,"<>P4 - Optional"),2),"n/a") -> 0 | M22: P2 | N22: Fridge Repair St Marys | Local Technicians, Same Day | O22: =LEN(N22) -> 52 | P22: Fridge Repair in St Marys | Q22: 600-800 | R22: - | S22: No - new find | T22: Tier 1: Semrush demand and/or both competitors cover it. Both Master and Fast have a page. See Suburb Pages tab for the unique-content checklist. Confirm you service this suburb before publishing.
A23: 22 | B23: Week 3 (2 - 8 Nov) | C23: NEW | D23: Suburb | E23: /fridge-repair-doonside/ | F23: fridge repair doonside | G23: <10 (not reported) | H23: n/a | I23: =COUNTIF(Keywords!$K$2:$K$140,E23) -> 0 | J23: =SUMIFS(Keywords!$D$2:$D$140,Keywords!$K$2:$K$140,E23,Keywords!$H$2:$H$140,"<>P4 - Optional") -> 0 | K23: =IFERROR(ROUND(AVERAGEIFS(Keywords!$E$2:$E$140,Keywords!$K$2:$K$140,E23,Keywords!$H$2:$H$140,"<>P4 - Optional"),1),"n/a") -> n/a | L23: =IFERROR(ROUND(AVERAGEIFS(Keywords!$F$2:$F$140,Keywords!$K$2:$K$140,E23,Keywords!$H$2:$H$140,"<>P4 - Optional"),2),"n/a") -> n/a | M23: P2 | N23: Fridge Repair Doonside | Local Technicians, Same Day | O23: =LEN(N23) -> 52 | P23: Fridge Repair in Doonside | Q23: 600-800 | R23: - | S23: Yes (planned) | T23: Tier 1: Semrush demand and/or both competitors cover it. Both Master and Fast have a page. See Suburb Pages tab for the unique-content checklist.
A24: 23 | B24: Week 3 (2 - 8 Nov) | C24: NEW | D24: Suburb | E24: /fridge-repair-mount-druitt/ | F24: fridge repair mount druitt | G24: <10 (not reported) | H24: n/a | I24: =COUNTIF(Keywords!$K$2:$K$140,E24) -> 0 | J24: =SUMIFS(Keywords!$D$2:$D$140,Keywords!$K$2:$K$140,E24,Keywords!$H$2:$H$140,"<>P4 - Optional") -> 0 | K24: =IFERROR(ROUND(AVERAGEIFS(Keywords!$E$2:$E$140,Keywords!$K$2:$K$140,E24,Keywords!$H$2:$H$140,"<>P4 - Optional"),1),"n/a") -> n/a | L24: =IFERROR(ROUND(AVERAGEIFS(Keywords!$F$2:$F$140,Keywords!$K$2:$K$140,E24,Keywords!$H$2:$H$140,"<>P4 - Optional"),2),"n/a") -> n/a | M24: P2 | N24: Fridge Repair Mount Druitt | Local Technicians, Same Day | O24: =LEN(N24) -> 56 | P24: Fridge Repair in Mount Druitt | Q24: 600-800 | R24: - | S24: Yes (planned) | T24: Tier 1: Semrush demand and/or both competitors cover it. Fast has a page. See Suburb Pages tab for the unique-content checklist.
A25: 24 | B25: Week 3 (2 - 8 Nov) | C25: NEW | D25: Suburb | E25: /fridge-repair-quakers-hill/ | F25: fridge repair quakers hill | G25: <10 (not reported) | H25: n/a | I25: =COUNTIF(Keywords!$K$2:$K$140,E25) -> 0 | J25: =SUMIFS(Keywords!$D$2:$D$140,Keywords!$K$2:$K$140,E25,Keywords!$H$2:$H$140,"<>P4 - Optional") -> 0 | K25: =IFERROR(ROUND(AVERAGEIFS(Keywords!$E$2:$E$140,Keywords!$K$2:$K$140,E25,Keywords!$H$2:$H$140,"<>P4 - Optional"),1),"n/a") -> n/a | L25: =IFERROR(ROUND(AVERAGEIFS(Keywords!$F$2:$F$140,Keywords!$K$2:$K$140,E25,Keywords!$H$2:$H$140,"<>P4 - Optional"),2),"n/a") -> n/a | M25: P2 | N25: Fridge Repair Quakers Hill | Local Technicians, Same Day | O25: =LEN(N25) -> 56 | P25: Fridge Repair in Quakers Hill | Q25: 600-800 | R25: - | S25: Yes (planned) | T25: Tier 1: Semrush demand and/or both competitors cover it. Fast has a page. See Suburb Pages tab for the unique-content checklist.
A26: 25 | B26: Week 3 (2 - 8 Nov) | C26: NEW | D26: Suburb | E26: /fridge-repair-seven-hills/ | F26: fridge repair seven hills | G26: <10 (not reported) | H26: n/a | I26: =COUNTIF(Keywords!$K$2:$K$140,E26) -> 0 | J26: =SUMIFS(Keywords!$D$2:$D$140,Keywords!$K$2:$K$140,E26,Keywords!$H$2:$H$140,"<>P4 - Optional") -> 0 | K26: =IFERROR(ROUND(AVERAGEIFS(Keywords!$E$2:$E$140,Keywords!$K$2:$K$140,E26,Keywords!$H$2:$H$140,"<>P4 - Optional"),1),"n/a") -> n/a | L26: =IFERROR(ROUND(AVERAGEIFS(Keywords!$F$2:$F$140,Keywords!$K$2:$K$140,E26,Keywords!$H$2:$H$140,"<>P4 - Optional"),2),"n/a") -> n/a | M26: P2 | N26: Fridge Repair Seven Hills | Local Technicians, Same Day | O26: =LEN(N26) -> 55 | P26: Fridge Repair in Seven Hills | Q26: 600-800 | R26: - | S26: Yes (planned) | T26: Tier 1: Semrush demand and/or both competitors cover it. Fast has a page. See Suburb Pages tab for the unique-content checklist.
A27: 26 | B27: Week 4 (9 - 15 Nov) | C27: NEW | D27: Brand | E27: /electrolux-fridge-repair/ | F27: electrolux refrigerator repair near me | G27: 110 | H27: 15 | I27: =COUNTIF(Keywords!$K$2:$K$140,E27) -> 3 | J27: =SUMIFS(Keywords!$D$2:$D$140,Keywords!$K$2:$K$140,E27,Keywords!$H$2:$H$140,"<>P4 - Optional") -> 290 | K27: =IFERROR(ROUND(AVERAGEIFS(Keywords!$E$2:$E$140,Keywords!$K$2:$K$140,E27,Keywords!$H$2:$H$140,"<>P4 - Optional"),1),"n/a") -> 12.3 | L27: =IFERROR(ROUND(AVERAGEIFS(Keywords!$F$2:$F$140,Keywords!$K$2:$K$140,E27,Keywords!$H$2:$H$140,"<>P4 - Optional"),2),"n/a") -> 1.75 | M27: P2 | N27: Electrolux Fridge Repair Blacktown | Local Techs | O27: =LEN(N27) -> 48 | P27: Electrolux Fridge Repair in Blacktown | Q27: 800-1,100 | R27: electrolux repair near me, electrolux repairs near me | S27: Yes (planned) | T27: Homepage brand list has Electrolux; no page yet.
A28: 27 | B28: Week 4 (9 - 15 Nov) | C28: NEW | D28: Service | E28: /fridge-door-seal-replacement/ | F28: fridge seal repair | G28: 90 | H28: 5 | I28: =COUNTIF(Keywords!$K$2:$K$140,E28) -> 3 | J28: =SUMIFS(Keywords!$D$2:$D$140,Keywords!$K$2:$K$140,E28,Keywords!$H$2:$H$140,"<>P4 - Optional") -> 210 | K28: =IFERROR(ROUND(AVERAGEIFS(Keywords!$E$2:$E$140,Keywords!$K$2:$K$140,E28,Keywords!$H$2:$H$140,"<>P4 - Optional"),1),"n/a") -> 8.3 | L28: =IFERROR(ROUND(AVERAGEIFS(Keywords!$F$2:$F$140,Keywords!$K$2:$K$140,E28,Keywords!$H$2:$H$140,"<>P4 - Optional"),2),"n/a") -> 0.9 | M28: P2 | N28: Fridge Door Seal Replacement Blacktown | Same Day | O28: =LEN(N28) -> 49 | P28: Fridge Door Seal Replacement in Blacktown | Q28: 800-1,000 | R28: fridge seal repairs, commercial fridge seal replacement service | S28: Yes (planned) | T28: Fast, cheap job = good conversion. Residential + commercial seals.
A29: 28 | B29: Week 4 (9 - 15 Nov) | C29: NEW | D29: Service | E29: /display-fridge-repair/ | F29: display fridge repair | G29: 50 | H29: 5 | I29: =COUNTIF(Keywords!$K$2:$K$140,E29) -> 1 | J29: =SUMIFS(Keywords!$D$2:$D$140,Keywords!$K$2:$K$140,E29,Keywords!$H$2:$H$140,"<>P4 - Optional") -> 50 | K29: =IFERROR(ROUND(AVERAGEIFS(Keywords!$E$2:$E$140,Keywords!$K$2:$K$140,E29,Keywords!$H$2:$H$140,"<>P4 - Optional"),1),"n/a") -> 5 | L29: =IFERROR(ROUND(AVERAGEIFS(Keywords!$F$2:$F$140,Keywords!$K$2:$K$140,E29,Keywords!$H$2:$H$140,"<>P4 - Optional"),2),"n/a") -> 0 | M29: P3 | N29: Display Fridge Repair Blacktown | Commercial Service | O29: =LEN(N29) -> 52 | P29: Display Fridge Repair in Blacktown | Q29: 800-1,100 | R29: - | S29: Yes (planned) | T29: Footer link exists but points to #services. Combine with deli / bakery / servery cabinets.
A30: 29 | B30: Week 4 (9 - 15 Nov) | C30: NEW | D30: Suburb | E30: /fridge-repair-rooty-hill/ | F30: fridge repair rooty hill | G30: <10 (not reported) | H30: n/a | I30: =COUNTIF(Keywords!$K$2:$K$140,E30) -> 0 | J30: =SUMIFS(Keywords!$D$2:$D$140,Keywords!$K$2:$K$140,E30,Keywords!$H$2:$H$140,"<>P4 - Optional") -> 0 | K30: =IFERROR(ROUND(AVERAGEIFS(Keywords!$E$2:$E$140,Keywords!$K$2:$K$140,E30,Keywords!$H$2:$H$140,"<>P4 - Optional"),1),"n/a") -> n/a | L30: =IFERROR(ROUND(AVERAGEIFS(Keywords!$F$2:$F$140,Keywords!$K$2:$K$140,E30,Keywords!$H$2:$H$140,"<>P4 - Optional"),2),"n/a") -> n/a | M30: P3 | N30: Fridge Repair Rooty Hill | Local Technicians, Same Day | O30: =LEN(N30) -> 54 | P30: Fridge Repair in Rooty Hill | Q30: 600-800 | R30: - | S30: Yes (planned) | T30: Tier 2: one competitor covers it. Master has a page. See Suburb Pages tab for the unique-content checklist.
A31: 30 | B31: Week 4 (9 - 15 Nov) | C31: NEW | D31: Suburb | E31: /fridge-repair-plumpton/ | F31: fridge repair plumpton | G31: <10 (not reported) | H31: n/a | I31: =COUNTIF(Keywords!$K$2:$K$140,E31) -> 0 | J31: =SUMIFS(Keywords!$D$2:$D$140,Keywords!$K$2:$K$140,E31,Keywords!$H$2:$H$140,"<>P4 - Optional") -> 0 | K31: =IFERROR(ROUND(AVERAGEIFS(Keywords!$E$2:$E$140,Keywords!$K$2:$K$140,E31,Keywords!$H$2:$H$140,"<>P4 - Optional"),1),"n/a") -> n/a | L31: =IFERROR(ROUND(AVERAGEIFS(Keywords!$F$2:$F$140,Keywords!$K$2:$K$140,E31,Keywords!$H$2:$H$140,"<>P4 - Optional"),2),"n/a") -> n/a | M31: P3 | N31: Fridge Repair Plumpton | Local Technicians, Same Day | O31: =LEN(N31) -> 52 | P31: Fridge Repair in Plumpton | Q31: 600-800 | R31: - | S31: Yes (planned) | T31: Tier 2: one competitor covers it. Master has a page. See Suburb Pages tab for the unique-content checklist.
A32: 31 | B32: Week 4 (9 - 15 Nov) | C32: NEW | D32: Suburb | E32: /fridge-repair-riverstone/ | F32: fridge repair riverstone | G32: <10 (not reported) | H32: n/a | I32: =COUNTIF(Keywords!$K$2:$K$140,E32) -> 0 | J32: =SUMIFS(Keywords!$D$2:$D$140,Keywords!$K$2:$K$140,E32,Keywords!$H$2:$H$140,"<>P4 - Optional") -> 0 | K32: =IFERROR(ROUND(AVERAGEIFS(Keywords!$E$2:$E$140,Keywords!$K$2:$K$140,E32,Keywords!$H$2:$H$140,"<>P4 - Optional"),1),"n/a") -> n/a | L32: =IFERROR(ROUND(AVERAGEIFS(Keywords!$F$2:$F$140,Keywords!$K$2:$K$140,E32,Keywords!$H$2:$H$140,"<>P4 - Optional"),2),"n/a") -> n/a | M32: P3 | N32: Fridge Repair Riverstone | Local Technicians, Same Day | O32: =LEN(N32) -> 54 | P32: Fridge Repair in Riverstone | Q32: 600-800 | R32: - | S32: Yes (planned) | T32: Tier 2: one competitor covers it. Master has a page. See Suburb Pages tab for the unique-content checklist.
A33: 32 | B33: Week 4 (9 - 15 Nov) | C33: NEW | D33: Suburb | E33: /fridge-repair-prospect/ | F33: fridge repair prospect | G33: <10 (not reported) | H33: n/a | I33: =COUNTIF(Keywords!$K$2:$K$140,E33) -> 0 | J33: =SUMIFS(Keywords!$D$2:$D$140,Keywords!$K$2:$K$140,E33,Keywords!$H$2:$H$140,"<>P4 - Optional") -> 0 | K33: =IFERROR(ROUND(AVERAGEIFS(Keywords!$E$2:$E$140,Keywords!$K$2:$K$140,E33,Keywords!$H$2:$H$140,"<>P4 - Optional"),1),"n/a") -> n/a | L33: =IFERROR(ROUND(AVERAGEIFS(Keywords!$F$2:$F$140,Keywords!$K$2:$K$140,E33,Keywords!$H$2:$H$140,"<>P4 - Optional"),2),"n/a") -> n/a | M33: P3 | N33: Fridge Repair Prospect | Local Technicians, Same Day | O33: =LEN(N33) -> 52 | P33: Fridge Repair in Prospect | Q33: 600-800 | R33: - | S33: Yes (planned) | T33: Tier 2: one competitor covers it. Fast has a page. See Suburb Pages tab for the unique-content checklist.
A34: 33 | B34: Week 4 (9 - 15 Nov) | C34: NEW | D34: Suburb | E34: /fridge-repair-lalor-park/ | F34: fridge repair lalor park | G34: <10 (not reported) | H34: n/a | I34: =COUNTIF(Keywords!$K$2:$K$140,E34) -> 0 | J34: =SUMIFS(Keywords!$D$2:$D$140,Keywords!$K$2:$K$140,E34,Keywords!$H$2:$H$140,"<>P4 - Optional") -> 0 | K34: =IFERROR(ROUND(AVERAGEIFS(Keywords!$E$2:$E$140,Keywords!$K$2:$K$140,E34,Keywords!$H$2:$H$140,"<>P4 - Optional"),1),"n/a") -> n/a | L34: =IFERROR(ROUND(AVERAGEIFS(Keywords!$F$2:$F$140,Keywords!$K$2:$K$140,E34,Keywords!$H$2:$H$140,"<>P4 - Optional"),2),"n/a") -> n/a | M34: P3 | N34: Fridge Repair Lalor Park | Local Technicians, Same Day | O34: =LEN(N34) -> 54 | P34: Fridge Repair in Lalor Park | Q34: 600-800 | R34: - | S34: Yes (planned) | T34: Tier 2: one competitor covers it. Fast has a page. See Suburb Pages tab for the unique-content checklist.
A35: 34 | B35: Week 4 (9 - 15 Nov) | C35: NEW | D35: Suburb | E35: /fridge-repair-glendenning/ | F35: fridge repair glendenning | G35: <10 (not reported) | H35: n/a | I35: =COUNTIF(Keywords!$K$2:$K$140,E35) -> 0 | J35: =SUMIFS(Keywords!$D$2:$D$140,Keywords!$K$2:$K$140,E35,Keywords!$H$2:$H$140,"<>P4 - Optional") -> 0 | K35: =IFERROR(ROUND(AVERAGEIFS(Keywords!$E$2:$E$140,Keywords!$K$2:$K$140,E35,Keywords!$H$2:$H$140,"<>P4 - Optional"),1),"n/a") -> n/a | L35: =IFERROR(ROUND(AVERAGEIFS(Keywords!$F$2:$F$140,Keywords!$K$2:$K$140,E35,Keywords!$H$2:$H$140,"<>P4 - Optional"),2),"n/a") -> n/a | M35: P3 | N35: Fridge Repair Glendenning | Local Technicians, Same Day | O35: =LEN(N35) -> 55 | P35: Fridge Repair in Glendenning | Q35: 600-800 | R35: - | S35: Yes (planned) | T35: Tier 2: one competitor covers it. Fast has a page. See Suburb Pages tab for the unique-content checklist.
A36: 35 | B36: Week 5 (16 - 22 Nov) | C36: NEW | D36: Service | E36: /bar-fridge-repair/ | F36: bar fridge repairs | G36: 70 | H36: 8 | I36: =COUNTIF(Keywords!$K$2:$K$140,E36) -> 2 | J36: =SUMIFS(Keywords!$D$2:$D$140,Keywords!$K$2:$K$140,E36,Keywords!$H$2:$H$140,"<>P4 - Optional") -> 120 | K36: =IFERROR(ROUND(AVERAGEIFS(Keywords!$E$2:$E$140,Keywords!$K$2:$K$140,E36,Keywords!$H$2:$H$140,"<>P4 - Optional"),1),"n/a") -> 9.5 | L36: =IFERROR(ROUND(AVERAGEIFS(Keywords!$F$2:$F$140,Keywords!$K$2:$K$140,E36,Keywords!$H$2:$H$140,"<>P4 - Optional"),2),"n/a") -> 1.43 | M36: P3 | N36: Bar & Mini Fridge Repair Blacktown | Fast Service | O36: =LEN(N36) -> 49 | P36: Bar Fridge & Mini Fridge Repair in Blacktown | Q36: 800-1,000 | R36: mini fridge repair | S36: Yes (planned) | T36: Small but easy win (KD 8-11).
A37: 36 | B37: Week 5 (16 - 22 Nov) | C37: NEW | D37: Suburb | E37: /fridge-repair-schofields/ | F37: fridge repair schofields | G37: <10 (not reported) | H37: n/a | I37: =COUNTIF(Keywords!$K$2:$K$140,E37) -> 0 | J37: =SUMIFS(Keywords!$D$2:$D$140,Keywords!$K$2:$K$140,E37,Keywords!$H$2:$H$140,"<>P4 - Optional") -> 0 | K37: =IFERROR(ROUND(AVERAGEIFS(Keywords!$E$2:$E$140,Keywords!$K$2:$K$140,E37,Keywords!$H$2:$H$140,"<>P4 - Optional"),1),"n/a") -> n/a | L37: =IFERROR(ROUND(AVERAGEIFS(Keywords!$F$2:$F$140,Keywords!$K$2:$K$140,E37,Keywords!$H$2:$H$140,"<>P4 - Optional"),2),"n/a") -> n/a | M37: P3 | N37: Fridge Repair Schofields | Local Technicians, Same Day | O37: =LEN(N37) -> 54 | P37: Fridge Repair in Schofields | Q37: 600-800 | R37: - | S37: Yes (planned) | T37: Tier 2: one competitor covers it. Fast has a page. See Suburb Pages tab for the unique-content checklist.
A38: 37 | B38: Week 5 (16 - 22 Nov) | C38: NEW | D38: Suburb | E38: /fridge-repair-the-ponds/ | F38: fridge repair the ponds | G38: <10 (not reported) | H38: n/a | I38: =COUNTIF(Keywords!$K$2:$K$140,E38) -> 0 | J38: =SUMIFS(Keywords!$D$2:$D$140,Keywords!$K$2:$K$140,E38,Keywords!$H$2:$H$140,"<>P4 - Optional") -> 0 | K38: =IFERROR(ROUND(AVERAGEIFS(Keywords!$E$2:$E$140,Keywords!$K$2:$K$140,E38,Keywords!$H$2:$H$140,"<>P4 - Optional"),1),"n/a") -> n/a | L38: =IFERROR(ROUND(AVERAGEIFS(Keywords!$F$2:$F$140,Keywords!$K$2:$K$140,E38,Keywords!$H$2:$H$140,"<>P4 - Optional"),2),"n/a") -> n/a | M38: P3 | N38: Fridge Repair The Ponds | Local Technicians, Same Day | O38: =LEN(N38) -> 53 | P38: Fridge Repair in The Ponds | Q38: 600-800 | R38: - | S38: Yes (planned) | T38: Tier 2: one competitor covers it. Fast has a page. See Suburb Pages tab for the unique-content checklist.
A39: 38 | B39: Week 5 (16 - 22 Nov) | C39: NEW | D39: Suburb | E39: /fridge-repair-kellyville-ridge/ | F39: fridge repair kellyville ridge | G39: <10 (not reported) | H39: n/a | I39: =COUNTIF(Keywords!$K$2:$K$140,E39) -> 0 | J39: =SUMIFS(Keywords!$D$2:$D$140,Keywords!$K$2:$K$140,E39,Keywords!$H$2:$H$140,"<>P4 - Optional") -> 0 | K39: =IFERROR(ROUND(AVERAGEIFS(Keywords!$E$2:$E$140,Keywords!$K$2:$K$140,E39,Keywords!$H$2:$H$140,"<>P4 - Optional"),1),"n/a") -> n/a | L39: =IFERROR(ROUND(AVERAGEIFS(Keywords!$F$2:$F$140,Keywords!$K$2:$K$140,E39,Keywords!$H$2:$H$140,"<>P4 - Optional"),2),"n/a") -> n/a | M39: P3 | N39: Fridge Repair Kellyville Ridge | Local Technicians, Same Day | O39: =LEN(N39) -> 60 | P39: Fridge Repair in Kellyville Ridge | Q39: 600-800 | R39: - | S39: Yes (planned) | T39: Tier 2: one competitor covers it. Fast has a page. See Suburb Pages tab for the unique-content checklist.
A40: 39 | B40: Week 5 (16 - 22 Nov) | C40: NEW | D40: Suburb | E40: /fridge-repair-pendle-hill/ | F40: fridge repair pendle hill | G40: <10 (not reported) | H40: n/a | I40: =COUNTIF(Keywords!$K$2:$K$140,E40) -> 0 | J40: =SUMIFS(Keywords!$D$2:$D$140,Keywords!$K$2:$K$140,E40,Keywords!$H$2:$H$140,"<>P4 - Optional") -> 0 | K40: =IFERROR(ROUND(AVERAGEIFS(Keywords!$E$2:$E$140,Keywords!$K$2:$K$140,E40,Keywords!$H$2:$H$140,"<>P4 - Optional"),1),"n/a") -> n/a | L40: =IFERROR(ROUND(AVERAGEIFS(Keywords!$F$2:$F$140,Keywords!$K$2:$K$140,E40,Keywords!$H$2:$H$140,"<>P4 - Optional"),2),"n/a") -> n/a | M40: P3 | N40: Fridge Repair Pendle Hill | Local Technicians, Same Day | O40: =LEN(N40) -> 55 | P40: Fridge Repair in Pendle Hill | Q40: 600-800 | R40: - | S40: Yes (planned) | T40: Tier 2: one competitor covers it. Fast has a page. See Suburb Pages tab for the unique-content checklist.
A41: 40 | B41: Week 5 (16 - 22 Nov) | C41: NEW | D41: Suburb | E41: /fridge-repair-wentworthville/ | F41: fridge repair wentworthville | G41: <10 (not reported) | H41: n/a | I41: =COUNTIF(Keywords!$K$2:$K$140,E41) -> 0 | J41: =SUMIFS(Keywords!$D$2:$D$140,Keywords!$K$2:$K$140,E41,Keywords!$H$2:$H$140,"<>P4 - Optional") -> 0 | K41: =IFERROR(ROUND(AVERAGEIFS(Keywords!$E$2:$E$140,Keywords!$K$2:$K$140,E41,Keywords!$H$2:$H$140,"<>P4 - Optional"),1),"n/a") -> n/a | L41: =IFERROR(ROUND(AVERAGEIFS(Keywords!$F$2:$F$140,Keywords!$K$2:$K$140,E41,Keywords!$H$2:$H$140,"<>P4 - Optional"),2),"n/a") -> n/a | M41: P3 | N41: Fridge Repair Wentworthville | Local Technicians, Same Day | O41: =LEN(N41) -> 58 | P41: Fridge Repair in Wentworthville | Q41: 600-800 | R41: - | S41: Yes (planned) | T41: Tier 2: one competitor covers it. Fast has a page. See Suburb Pages tab for the unique-content checklist.
A42: 41 | B42: Week 6 (23 - 29 Nov) | C42: NEW | D42: Hub | E42: /fridge-repair-sydney/ | F42: fridge repair in sydney | G42: 110 | H42: 14 | I42: =COUNTIF(Keywords!$K$2:$K$140,E42) -> 15 | J42: =SUMIFS(Keywords!$D$2:$D$140,Keywords!$K$2:$K$140,E42,Keywords!$H$2:$H$140,"<>P4 - Optional") -> 160 | K42: =IFERROR(ROUND(AVERAGEIFS(Keywords!$E$2:$E$140,Keywords!$K$2:$K$140,E42,Keywords!$H$2:$H$140,"<>P4 - Optional"),1),"n/a") -> 11.5 | L42: =IFERROR(ROUND(AVERAGEIFS(Keywords!$F$2:$F$140,Keywords!$K$2:$K$140,E42,Keywords!$H$2:$H$140,"<>P4 - Optional"),2),"n/a") -> 2.01 | M42: P3 | N42: Fridge Repair Sydney | Western Sydney Technicians | O42: =LEN(N42) -> 49 | P42: Fridge Repair Across Sydney | Q42: 900-1,200 | R42: refrigerator repair sydney, fridge repairs potts point, fridge repairs double bay, fridge repairs coogee, fridge repair inner west, fridge repairs eastern suburbs, fridge repairs bondi, fridge repairs darlinghurst (+6 more in Keywords tab) | S42: No - new find | T42: One hub page for Sydney-wide + inner west / eastern suburbs searches instead of 13 thin suburb pages. Publish only if you travel there.
A43: 42 | B43: Week 6 (23 - 29 Nov) | C43: NEW | D43: Service | E43: /fridge-compressor-repair/ | F43: refrigeration compressor repairs | G43: 90 | H43: 4 | I43: =COUNTIF(Keywords!$K$2:$K$140,E43) -> 1 | J43: =SUMIFS(Keywords!$D$2:$D$140,Keywords!$K$2:$K$140,E43,Keywords!$H$2:$H$140,"<>P4 - Optional") -> 90 | K43: =IFERROR(ROUND(AVERAGEIFS(Keywords!$E$2:$E$140,Keywords!$K$2:$K$140,E43,Keywords!$H$2:$H$140,"<>P4 - Optional"),1),"n/a") -> 4 | L43: =IFERROR(ROUND(AVERAGEIFS(Keywords!$F$2:$F$140,Keywords!$K$2:$K$140,E43,Keywords!$H$2:$H$140,"<>P4 - Optional"),2),"n/a") -> 0 | M43: P3 | N43: Fridge Compressor Repair Blacktown | Fast Diagnosis | O43: =LEN(N43) -> 51 | P43: Fridge Compressor Repair & Replacement in Blacktown | Q43: 800-1,000 | R43: - | S43: No - new find | T43: Support page for regas / not-cooling / noisy fridge.
A44: 43 | B44: Week 6 (23 - 29 Nov) | C44: NEW | D44: Suburb | E44: /fridge-repair-greystanes/ | F44: fridge repair greystanes | G44: <10 (not reported) | H44: n/a | I44: =COUNTIF(Keywords!$K$2:$K$140,E44) -> 0 | J44: =SUMIFS(Keywords!$D$2:$D$140,Keywords!$K$2:$K$140,E44,Keywords!$H$2:$H$140,"<>P4 - Optional") -> 0 | K44: =IFERROR(ROUND(AVERAGEIFS(Keywords!$E$2:$E$140,Keywords!$K$2:$K$140,E44,Keywords!$H$2:$H$140,"<>P4 - Optional"),1),"n/a") -> n/a | L44: =IFERROR(ROUND(AVERAGEIFS(Keywords!$F$2:$F$140,Keywords!$K$2:$K$140,E44,Keywords!$H$2:$H$140,"<>P4 - Optional"),2),"n/a") -> n/a | M44: P3 | N44: Fridge Repair Greystanes | Local Technicians, Same Day | O44: =LEN(N44) -> 54 | P44: Fridge Repair in Greystanes | Q44: 600-800 | R44: - | S44: Yes (planned) | T44: Tier 2: one competitor covers it. Fast has a page. See Suburb Pages tab for the unique-content checklist.
A45: 44 | B45: Week 6 (23 - 29 Nov) | C45: NEW | D45: Suburb | E45: /fridge-repair-kings-park/ | F45: fridge repair kings park | G45: <10 (not reported) | H45: n/a | I45: =COUNTIF(Keywords!$K$2:$K$140,E45) -> 0 | J45: =SUMIFS(Keywords!$D$2:$D$140,Keywords!$K$2:$K$140,E45,Keywords!$H$2:$H$140,"<>P4 - Optional") -> 0 | K45: =IFERROR(ROUND(AVERAGEIFS(Keywords!$E$2:$E$140,Keywords!$K$2:$K$140,E45,Keywords!$H$2:$H$140,"<>P4 - Optional"),1),"n/a") -> n/a | L45: =IFERROR(ROUND(AVERAGEIFS(Keywords!$F$2:$F$140,Keywords!$K$2:$K$140,E45,Keywords!$H$2:$H$140,"<>P4 - Optional"),2),"n/a") -> n/a | M45: P3 | N45: Fridge Repair Kings Park | Local Technicians, Same Day | O45: =LEN(N45) -> 54 | P45: Fridge Repair in Kings Park | Q45: 600-800 | R45: - | S45: Yes (planned) | T45: Tier 3: no competitor page - lowest effort to rank, lowest volume. NO competitor has a page here - easy local win. See Suburb Pages tab for the unique-content checklist.
A46: 45 | B46: Week 6 (23 - 29 Nov) | C46: NEW | D46: Suburb | E46: /fridge-repair-marayong/ | F46: fridge repair marayong | G46: <10 (not reported) | H46: n/a | I46: =COUNTIF(Keywords!$K$2:$K$140,E46) -> 0 | J46: =SUMIFS(Keywords!$D$2:$D$140,Keywords!$K$2:$K$140,E46,Keywords!$H$2:$H$140,"<>P4 - Optional") -> 0 | K46: =IFERROR(ROUND(AVERAGEIFS(Keywords!$E$2:$E$140,Keywords!$K$2:$K$140,E46,Keywords!$H$2:$H$140,"<>P4 - Optional"),1),"n/a") -> n/a | L46: =IFERROR(ROUND(AVERAGEIFS(Keywords!$F$2:$F$140,Keywords!$K$2:$K$140,E46,Keywords!$H$2:$H$140,"<>P4 - Optional"),2),"n/a") -> n/a | M46: P3 | N46: Fridge Repair Marayong | Local Technicians, Same Day | O46: =LEN(N46) -> 52 | P46: Fridge Repair in Marayong | Q46: 600-800 | R46: - | S46: Yes (planned) | T46: Tier 3: no competitor page - lowest effort to rank, lowest volume. NO competitor has a page here - easy local win. See Suburb Pages tab for the unique-content checklist.
A47: 46 | B47: Week 6 (23 - 29 Nov) | C47: NEW | D47: Suburb | E47: /fridge-repair-kings-langley/ | F47: fridge repair kings langley | G47: <10 (not reported) | H47: n/a | I47: =COUNTIF(Keywords!$K$2:$K$140,E47) -> 0 | J47: =SUMIFS(Keywords!$D$2:$D$140,Keywords!$K$2:$K$140,E47,Keywords!$H$2:$H$140,"<>P4 - Optional") -> 0 | K47: =IFERROR(ROUND(AVERAGEIFS(Keywords!$E$2:$E$140,Keywords!$K$2:$K$140,E47,Keywords!$H$2:$H$140,"<>P4 - Optional"),1),"n/a") -> n/a | L47: =IFERROR(ROUND(AVERAGEIFS(Keywords!$F$2:$F$140,Keywords!$K$2:$K$140,E47,Keywords!$H$2:$H$140,"<>P4 - Optional"),2),"n/a") -> n/a | M47: P3 | N47: Fridge Repair Kings Langley | Local Technicians, Same Day | O47: =LEN(N47) -> 57 | P47: Fridge Repair in Kings Langley | Q47: 600-800 | R47: - | S47: Yes (planned) | T47: Tier 3: no competitor page - lowest effort to rank, lowest volume. NO competitor has a page here - easy local win. See Suburb Pages tab for the unique-content checklist.
A48: 47 | B48: Week 6 (23 - 29 Nov) | C48: NEW | D48: Suburb | E48: /fridge-repair-woodcroft/ | F48: fridge repair woodcroft | G48: <10 (not reported) | H48: n/a | I48: =COUNTIF(Keywords!$K$2:$K$140,E48) -> 0 | J48: =SUMIFS(Keywords!$D$2:$D$140,Keywords!$K$2:$K$140,E48,Keywords!$H$2:$H$140,"<>P4 - Optional") -> 0 | K48: =IFERROR(ROUND(AVERAGEIFS(Keywords!$E$2:$E$140,Keywords!$K$2:$K$140,E48,Keywords!$H$2:$H$140,"<>P4 - Optional"),1),"n/a") -> n/a | L48: =IFERROR(ROUND(AVERAGEIFS(Keywords!$F$2:$F$140,Keywords!$K$2:$K$140,E48,Keywords!$H$2:$H$140,"<>P4 - Optional"),2),"n/a") -> n/a | M48: P3 | N48: Fridge Repair Woodcroft | Local Technicians, Same Day | O48: =LEN(N48) -> 53 | P48: Fridge Repair in Woodcroft | Q48: 600-800 | R48: - | S48: Yes (planned) | T48: Tier 3: no competitor page - lowest effort to rank, lowest volume. NO competitor has a page here - easy local win. See Suburb Pages tab for the unique-content checklist.
...

Sheet Suburb Pages
A1: Suburb page plan - 4 tiers (Semrush AU + competitor sitemaps, 16 Oct 2026)
A2: Rule: a suburb page goes live only with unique local content. Checklist for EVERY page:
A3: 1. Real suburb details: postcode, 3-5 nearby streets / landmarks / shopping centre, typical local housing (units, townhouses, older homes) - from your own knowledge of the jobs.
A4: 2. At least 2 real jobs done in that suburb (fault, brand, fix, time to complete) + photo with suburb in the caption / alt text; add a real review from a customer in that suburb when available.
A5: 3. Own FAQ (3-5 questions that differ per suburb: travel time, same-day availability, call-out fee, common brands in that area), embedded map, phone number and booking form above the fold.
A6: 4. Internal links: to the 3 most relevant service pages, 2 brand pages, /service-areas/ and 2 neighbouring suburb pages. Link to it from /service-areas/ and the homepage area section.
A7: 5. Never copy a page and only replace the suburb name. After 8 weeks, merge or noindex any suburb page that has zero impressions in Search Console.
A9: Tier | B9: Publish Week | C9: Suburb | D9: Postcode (verify) | E9: Region | F9: On your homepage service list? | G9: URL | H9: Semrush AU vol/mo | I9: KD % | J9: Master Fridge Repairs has page? | K9: Fast Fridge Repairs has page? | L9: Best competitor visits/mo on that suburb page | M9: Priority | N9: Why this tier
A10: Tier 1 | B10: Week 2 (26 Oct - 1 Nov) | C10: Penrith | D10: 2750 | E10: West | F10: No - confirm you service it | G10: /fridge-repair-penrith/ | H10: 280 | I10: 6 | J10: Yes | K10: Yes | L10: 14 | M10: P2 | N10: Semrush demand and / or both competitors have this page
A11: Tier 1 | B11: Week 2 (26 Oct - 1 Nov) | C11: Smithfield | D11: 2164 | E11: West | F11: No - confirm you service it | G11: /fridge-repair-smithfield/ | H11: 170 | I11: 5 | J11: Yes | K11: Yes | L11: 0 | M11: P2 | N11: Semrush demand and / or both competitors have this page
A12: Tier 1 | B12: Week 2 (26 Oct - 1 Nov) | C12: Parramatta | D12: 2150 | E12: Central-west | F12: No - confirm you service it | G12: /fridge-repair-parramatta/ | H12: 140 | I12: 5 | J12: Yes | K12: Yes | L12: 6 | M12: P2 | N12: Semrush demand and / or both competitors have this page
A13: Tier 1 | B13: Week 2 (26 Oct - 1 Nov) | C13: Castle Hill | D13: 2154 | E13: Hills District | F13: No - confirm you service it | G13: /fridge-repair-castle-hill/ | H13: 140 | I13: 4 | J13: Yes | K13: Yes | L13: 13 | M13: P2 | N13: Semrush demand and / or both competitors have this page
A14: Tier 1 | B14: Week 2 (26 Oct - 1 Nov) | C14: Glenwood | D14: 2768 | E14: North-west | F14: Yes | G14: /fridge-repair-glenwood/ | H14: 70 | I14: 4 | J14: No | K14: Yes | L14: 1 | M14: P2 | N14: Semrush demand and / or both competitors have this page
A15: Tier 1 | B15: Week 2 (26 Oct - 1 Nov) | C15: Rouse Hill | D15: 2155 | E15: North-west | F15: Yes | G15: /fridge-repair-rouse-hill/ | H15: 50 | I15: 4 | J15: Yes | K15: Yes | L15: 0 | M15: P2 | N15: Semrush demand and / or both competitors have this page
A16: Tier 1 | B16: Week 3 (2 - 8 Nov) | C16: St Marys | D16: 2760 | E16: West | F16: No - confirm you service it | G16: /fridge-repair-st-marys/ | H16: 50 | I16: 6 | J16: Yes | K16: Yes | L16: 2 | M16: P2 | N16: Semrush demand and / or both competitors have this page
A17: Tier 1 | B17: Week 3 (2 - 8 Nov) | C17: Doonside | D17: 2767 | E17: West | F17: Yes | G17: /fridge-repair-doonside/ | H17: <10 (not reported) | I17: n/a | J17: Yes | K17: Yes | L17: 0 | M17: P2 | N17: Semrush demand and / or both competitors have this page
A18: Tier 1 | B18: Week 3 (2 - 8 Nov) | C18: Mount Druitt | D18: 2770 | E18: West | F18: Yes | G18: /fridge-repair-mount-druitt/ | H18: <10 (not reported) | I18: n/a | J18: No | K18: Yes | L18: 0 | M18: P2 | N18: Semrush demand and / or both competitors have this page
A19: Tier 1 | B19: Week 3 (2 - 8 Nov) | C19: Quakers Hill | D19: 2763 | E19: North-west | F19: Yes | G19: /fridge-repair-quakers-hill/ | H19: <10 (not reported) | I19: n/a | J19: No | K19: Yes | L19: 0 | M19: P2 | N19: Semrush demand and / or both competitors have this page
A20: Tier 1 | B20: Week 3 (2 - 8 Nov) | C20: Seven Hills | D20: 2147 | E20: Central | F20: Yes | G20: /fridge-repair-seven-hills/ | H20: <10 (not reported) | I20: n/a | J20: No | K20: Yes | L20: 0 | M20: P2 | N20: Semrush demand and / or both competitors have this page
A21: Tier 2 | B21: Week 3 (2 - 8 Nov) | C21: Richmond | D21: 2753 | E21: Hawkesbury | F21: No - confirm you service it | G21: /fridge-repair-richmond/ | H21: 90 | I21: 6 | J21: Yes | K21: Yes | L21: 5 | M21: P3 | N21: One competitor has this page - proven local demand, moderate effort
A22: Tier 2 | B22: Week 4 (9 - 15 Nov) | C22: Rooty Hill | D22: 2766 | E22: West | F22: Yes | G22: /fridge-repair-rooty-hill/ | H22: <10 (not reported) | I22: n/a | J22: Yes | K22: No | L22: 0 | M22: P3 | N22: One competitor has this page - proven local demand, moderate effort
A23: Tier 2 | B23: Week 4 (9 - 15 Nov) | C23: Plumpton | D23: 2761 | E23: West | F23: Yes | G23: /fridge-repair-plumpton/ | H23: <10 (not reported) | I23: n/a | J23: Yes | K23: No | L23: 0 | M23: P3 | N23: One competitor has this page - proven local demand, moderate effort
A24: Tier 2 | B24: Week 4 (9 - 15 Nov) | C24: Riverstone | D24: 2765 | E24: North-west | F24: Yes | G24: /fridge-repair-riverstone/ | H24: <10 (not reported) | I24: n/a | J24: Yes | K24: No | L24: 0 | M24: P3 | N24: One competitor has this page - proven local demand, moderate effort
A25: Tier 2 | B25: Week 4 (9 - 15 Nov) | C25: Prospect | D25: 2148 | E25: Central | F25: Yes | G25: /fridge-repair-prospect/ | H25: <10 (not reported) | I25: n/a | J25: No | K25: Yes | L25: 0 | M25: P3 | N25: One competitor has this page - proven local demand, moderate effort
A26: Tier 2 | B26: Week 4 (9 - 15 Nov) | C26: Lalor Park | D26: 2147 | E26: Central | F26: Yes | G26: /fridge-repair-lalor-park/ | H26: <10 (not reported) | I26: n/a | J26: No | K26: Yes | L26: 0 | M26: P3 | N26: One competitor has this page - proven local demand, moderate effort
A27: Tier 2 | B27: Week 4 (9 - 15 Nov) | C27: Glendenning | D27: 2761 | E27: West | F27: Yes | G27: /fridge-repair-glendenning/ | H27: <10 (not reported) | I27: n/a | J27: No | K27: Yes | L27: 0 | M27: P3 | N27: One competitor has this page - proven local demand, moderate effort
A28: Tier 2 | B28: Week 5 (16 - 22 Nov) | C28: Schofields | D28: 2762 | E28: North-west | F28: Yes | G28: /fridge-repair-schofields/ | H28: <10 (not reported) | I28: n/a | J28: No | K28: Yes | L28: 0 | M28: P3 | N28: One competitor has this page - proven local demand, moderate effort
A29: Tier 2 | B29: Week 5 (16 - 22 Nov) | C29: The Ponds | D29: 2769 | E29: North-west | F29: Yes | G29: /fridge-repair-the-ponds/ | H29: <10 (not reported) | I29: n/a | J29: No | K29: Yes | L29: 0 | M29: P3 | N29: One competitor has this page - proven local demand, moderate effort
A30: Tier 2 | B30: Week 5 (16 - 22 Nov) | C30: Kellyville Ridge | D30: 2155 | E30: North-west | F30: Yes | G30: /fridge-repair-kellyville-ridge/ | H30: <10 (not reported) | I30: n/a | J30: No | K30: Yes | L30: 0 | M30: P3 | N30: One competitor has this page - proven local demand, moderate effort
A31: Tier 2 | B31: Week 5 (16 - 22 Nov) | C31: Pendle Hill | D31: 2145 | E31: East | F31: Yes | G31: /fridge-repair-pendle-hill/ | H31: <10 (not reported) | I31: n/a | J31: No | K31: Yes | L31: 0 | M31: P3 | N31: One competitor has this page - proven local demand, moderate effort
A32: Tier 2 | B32: Week 5 (16 - 22 Nov) | C32: Wentworthville | D32: 2145 | E32: East | F32: Yes | G32: /fridge-repair-wentworthville/ | H32: <10 (not reported) | I32: n/a | J32: No | K32: Yes | L32: 0 | M32: P3 | N32: One competitor has this page - proven local demand, moderate effort
A33: Tier 2 | B33: Week 6 (23 - 29 Nov) | C33: Greystanes | D33: 2145 | E33: East | F33: Yes | G33: /fridge-repair-greystanes/ | H33: <10 (not reported) | I33: n/a | J33: No | K33: Yes | L33: 0 | M33: P3 | N33: One competitor has this page - proven local demand, moderate effort
A34: Tier 3 | B34: Week 6 (23 - 29 Nov) | C34: Kings Park | D34: 2148 | E34: Central | F34: Yes | G34: /fridge-repair-kings-park/ | H34: <10 (not reported) | I34: n/a | J34: No | K34: No | L34: - | M34: P3 | N34: No competitor page in this suburb - easy to rank, very low volume
A35: Tier 3 | B35: Week 6 (23 - 29 Nov) | C35: Marayong | D35: 2148 | E35: Central | F35: Yes | G35: /fridge-repair-marayong/ | H35: <10 (not reported) | I35: n/a | J35: No | K35: No | L35: - | M35: P3 | N35: No competitor page in this suburb - easy to rank, very low volume
A36: Tier 3 | B36: Week 6 (23 - 29 Nov) | C36: Kings Langley | D36: 2147 | E36: Central | F36: Yes | G36: /fridge-repair-kings-langley/ | H36: <10 (not reported) | I36: n/a | J36: No | K36: No | L36: - | M36: P3 | N36: No competitor page in this suburb - easy to rank, very low volume
A37: Tier 3 | B37: Week 6 (23 - 29 Nov) | C37: Woodcroft | D37: 2767 | E37: West | F37: Yes | G37: /fridge-repair-woodcroft/ | H37: <10 (not reported) | I37: n/a | J37: No | K37: No | L37: - | M37: P3 | N37: No competitor page in this suburb - easy to rank, very low volume
A38: Tier 3 | B38: Week 6 (23 - 29 Nov) | C38: Minchinbury | D38: 2770 | E38: West | F38: Yes | G38: /fridge-repair-minchinbury/ | H38: <10 (not reported) | I38: n/a | J38: No | K38: No | L38: - | M38: P3 | N38: No competitor page in this suburb - easy to rank, very low volume
A39: Tier 3 | B39: Week 7 (30 Nov - 6 Dec) | C39: St Clair | D39: 2759 | E39: West | F39: Yes | G39: /fridge-repair-st-clair/ | H39: <10 (not reported) | I39: n/a | J39: No | K39: No | L39: - | M39: P3 | N39: No competitor page in this suburb - easy to rank, very low volume
A40: Tier 3 | B40: Week 7 (30 Nov - 6 Dec) | C40: Acacia Gardens | D40: 2763 | E40: North-west | F40: Yes | G40: /fridge-repair-acacia-gardens/ | H40: <10 (not reported) | I40: n/a | J40: No | K40: No | L40: - | M40: P3 | N40: No competitor page in this suburb - easy to rank, very low volume
A41: Tier 3 | B41: Week 7 (30 Nov - 6 Dec) | C41: Marsden Park | D41: 2765 | E41: North-west | F41: Yes | G41: /fridge-repair-marsden-park/ | H41: <10 (not reported) | I41: n/a | J41: No | K41: No | L41: - | M41: P3 | N41: No competitor page in this suburb - easy to rank, very low volume
...

Sheet Keywords
A1: # | B1: Keyword | C1: Search Intent (Semrush) | D1: Volume (AU/mo) | E1: KD % | F1: CPC (USD) | G1: Opportunity Score | H1: Priority | I1: Cluster | J1: Local Relevance | K1: Target Page | L1: Page Status | M1: Role | N1: In previous plan? | O1: Previous plan target page
A2: 1 | B2: fridge repairs near me | C2: Transactional | D2: 2400 | E2: 12 | F2: 2.11 | G2: =ROUND(D2*(100-E2)/100,0) -> 2112 | H2: P1 | I2: Near Me / Mechanic | J2: Core | K2: / | L2: EXISTING PAGE | M2: PRIMARY | N2: Yes | O2: /
A3: 2 | B3: fridge repairs | C3: Commercial | D3: 1600 | E3: 16 | F3: 1.98 | G3: =ROUND(D3*(100-E3)/100,0) -> 1344 | H3: P1 | I3: Core Fridge Repair | J3: Core | K3: / | L3: EXISTING PAGE | M3: Secondary | N3: No - new find
A4: 3 | B4: fridge repair | C4: Commercial | D4: 1300 | E4: 14 | F4: 1.98 | G4: =ROUND(D4*(100-E4)/100,0) -> 1118 | H4: P1 | I4: Core Fridge Repair | J4: Core | K4: / | L4: EXISTING PAGE | M4: Secondary | N4: No - new find
A5: 4 | B5: fisher and paykel fridge repairs | C5: Transactional | D5: 1000 | E5: 12 | F5: 1.46 | G5: =ROUND(D5*(100-E5)/100,0) -> 880 | H5: P1 | I5: Brands | J5: Core | K5: /fisher-paykel-fridge-repair/ | L5: NEW PAGE | M5: PRIMARY | N5: Yes | O5: /fisher-and-paykel-fridge-repair/
A6: 5 | B6: repair refrigerator service | C6: Commercial | D6: 720 | E6: 13 | F6: 3.22 | G6: =ROUND(D6*(100-E6)/100,0) -> 626 | H6: P1 | I6: Residential Service | J6: Core | K6: /residential-fridge-repair/ | L6: EXISTING PAGE | M6: PRIMARY | N6: No - new find
A7: 6 | B7: commercial refrigeration repair | C7: Commercial | D7: 720 | E7: 14 | F7: 10.31 | G7: =ROUND(D7*(100-E7)/100,0) -> 619 | H7: P1 | I7: Commercial Refrigeration | J7: Core | K7: /commercial-fridge-repair-blacktown/ | L7: EXISTING PAGE | M7: PRIMARY | N7: Yes | O7: /commercial-fridge-repair-blacktown/
A8: 7 | B8: fridge service and repair | C8: Commercial | D8: 720 | E8: 15 | F8: 2.47 | G8: =ROUND(D8*(100-E8)/100,0) -> 612 | H8: P1 | I8: Residential Service | J8: Core | K8: /residential-fridge-repair/ | L8: EXISTING PAGE | M8: Secondary | N8: No - new find
A9: 8 | B9: commercial freezer repair | C9: Commercial | D9: 590 | E9: 10 | F9: 10.78 | G9: =ROUND(D9*(100-E9)/100,0) -> 531 | H9: P1 | I9: Commercial Refrigeration | J9: Core | K9: /commercial-fridge-repair-blacktown/ | L9: EXISTING PAGE | M9: Secondary | N9: Yes | O9: /commercial-fridge-repair-blacktown/
A10: 9 | B10: westinghouse refrigerator repairs | C10: Commercial | D10: 590 | E10: 13 | F10: 2.38 | G10: =ROUND(D10*(100-E10)/100,0) -> 513 | H10: P1 | I10: Brands | J10: Core | K10: /westinghouse-fridge-repair/ | L10: NEW PAGE | M10: PRIMARY | N10: No - new find
A11: 10 | B11: fisher & paykel fridge repairs | C11: Transactional | D11: 590 | E11: 15 | F11: 1.48 | G11: =ROUND(D11*(100-E11)/100,0) -> 502 | H11: P1 | I11: Brands | J11: Core | K11: /fisher-paykel-fridge-repair/ | L11: NEW PAGE | M11: Secondary | N11: No - new find
A12: 11 | B12: fisher and paykel refrigerator repair | C12: Transactional | D12: 590 | E12: 17 | F12: 1.48 | G12: =ROUND(D12*(100-E12)/100,0) -> 490 | H12: P1 | I12: Brands | J12: Core | K12: /fisher-paykel-fridge-repair/ | L12: NEW PAGE | M12: Secondary | N12: Yes | O12: /fisher-and-paykel-fridge-repair/
A13: 12 | B13: commercial fridge repair | C13: Commercial | D13: 590 | E13: 18 | F13: 10.78 | G13: =ROUND(D13*(100-E13)/100,0) -> 484 | H13: P1 | I13: Commercial Refrigeration | J13: Core | K13: /commercial-fridge-repair-blacktown/ | L13: EXISTING PAGE | M13: Secondary | N13: Yes | O13: /commercial-fridge-repair-blacktown/
A14: 13 | B14: freezer repair | C14: Commercial | D14: 480 | E14: 7 | F14: 2.26 | G14: =ROUND(D14*(100-E14)/100,0) -> 446 | H14: P1 | I14: Freezer | J14: Core | K14: /freezer-repair-blacktown/ | L14: EXISTING PAGE | M14: PRIMARY | N14: No - new find
A15: 14 | B15: refrigerator mechanic near me | C15: Transactional | D15: 480 | E15: 16 | F15: 2.33 | G15: =ROUND(D15*(100-E15)/100,0) -> 403 | H15: P1 | I15: Near Me / Mechanic | J15: Core | K15: / | L15: EXISTING PAGE | M15: Secondary | N15: No - new find
A16: 15 | B16: commercial refrigeration repairs | C16: Commercial | D16: 480 | E16: 17 | F16: 6.91 | G16: =ROUND(D16*(100-E16)/100,0) -> 398 | H16: P1 | I16: Commercial Refrigeration | J16: Core | K16: /commercial-fridge-repair-blacktown/ | L16: EXISTING PAGE | M16: Secondary | N16: No - new find
A17: 16 | B17: refrigerator repair service | C17: Commercial | D17: 480 | E17: 18 | F17: 2.47 | G17: =ROUND(D17*(100-E17)/100,0) -> 394 | H17: P1 | I17: Residential Service | J17: Core | K17: /residential-fridge-repair/ | L17: EXISTING PAGE | M17: Secondary | N17: No - new find
A18: 17 | B18: commercial refrigeration services | C18: Commercial | D18: 390 | E18: 18 | F18: 6.45 | G18: =ROUND(D18*(100-E18)/100,0) -> 320 | H18: P1 | I18: Commercial Refrigeration | J18: Core | K18: /commercial-fridge-repair-blacktown/ | L18: EXISTING PAGE | M18: Secondary | N18: No - new find
A19: 18 | B19: refrigerator ice machine repair | C19: Transactional | D19: 320 | E19: 6 | F19: 4.16 | G19: =ROUND(D19*(100-E19)/100,0) -> 301 | H19: P1 | I19: Ice Machine | J19: Core | K19: /ice-machine-repair/ | L19: NEW PAGE | M19: PRIMARY | N19: No - new find
A20: 19 | B20: fridge technician near me | C20: Transactional | D20: 320 | E20: 16 | F20: 2.34 | G20: =ROUND(D20*(100-E20)/100,0) -> 269 | H20: P1 | I20: Near Me / Mechanic | J20: Core | K20: / | L20: EXISTING PAGE | M20: Secondary | N20: Yes | O20: /
A21: 20 | B21: fridge mechanic | C21: Commercial | D21: 260 | E21: 10 | F21: 2.14 | G21: =ROUND(D21*(100-E21)/100,0) -> 234 | H21: P1 | I21: Near Me / Mechanic | J21: Core | K21: / | L21: EXISTING PAGE | M21: Secondary | N21: No - new find
A22: 21 | B22: lg fridge repair near me | C22: Transactional | D22: 260 | E22: 11 | F22: 1.58 | G22: =ROUND(D22*(100-E22)/100,0) -> 231 | H22: P1 | I22: Brands | J22: Core | K22: /lg-fridge-repair/ | L22: NEW PAGE | M22: PRIMARY | N22: Yes | O22: /lg-fridge-repair/
A23: 22 | B23: lg fridge repairs near me | C23: Transactional | D23: 260 | E23: 11 | F23: 1.58 | G23: =ROUND(D23*(100-E23)/100,0) -> 231 | H23: P1 | I23: Brands | J23: Core | K23: /lg-fridge-repair/ | L23: NEW PAGE | M23: Secondary | N23: No - new find
A24: 23 | B24: lg refrigerator repair near me | C24: Transactional | D24: 260 | E24: 11 | F24: 1.58 | G24: =ROUND(D24*(100-E24)/100,0) -> 231 | H24: P1 | I24: Brands | J24: Core | K24: /lg-fridge-repair/ | L24: NEW PAGE | M24: Secondary | N24: No - new find
A25: 24 | B25: fisher and paykel appliance repairs | C25: Transactional / Navigational | D25: 260 | E25: 17 | F25: 1.51 | G25: =ROUND(D25*(100-E25)/100,0) -> 216 | H25: P1 | I25: Brands | J25: Core | K25: /fisher-paykel-fridge-repair/ | L25: NEW PAGE | M25: Secondary | N25: No - new find
A26: 25 | B26: fisher and paykel repair service near me | C26: Transactional / Navigational | D26: 260 | E26: 17 | F26: 1.59 | G26: =ROUND(D26*(100-E26)/100,0) -> 216 | H26: P1 | I26: Brands | J26: Core | K26: /fisher-paykel-fridge-repair/ | L26: NEW PAGE | M26: Secondary | N26: No - new find
A27: 26 | B27: fisher and paykel service repair | C27: Transactional / Navigational | D27: 260 | E27: 17 | F27: 1.51 | G27: =ROUND(D27*(100-E27)/100,0) -> 216 | H27: P1 | I27: Brands | J27: Core | K27: /fisher-paykel-fridge-repair/ | L27: NEW PAGE | M27: Secondary | N27: No - new find
A28: 27 | B28: fisher paykel appliance repair near me | C28: Transactional | D28: 210 | E28: 4 | F28: 1.66 | G28: =ROUND(D28*(100-E28)/100,0) -> 202 | H28: P1 | I28: Brands | J28: Core | K28: /fisher-paykel-fridge-repair/ | L28: NEW PAGE | M28: Secondary | N28: No - new find
A29: 28 | B29: emergency commercial refrigeration repair | C29: Commercial | D29: 210 | E29: 5 | F29: 0 | G29: =ROUND(D29*(100-E29)/100,0) -> 200 | H29: P1 | I29: Emergency / Same-day | J29: Core | K29: /emergency-fridge-repair/ | L29: EXISTING PAGE | M29: PRIMARY | N29: No - new find
A30: 29 | B30: refrigeration service | C30: Commercial | D30: 210 | E30: 6 | F30: 3.83 | G30: =ROUND(D30*(100-E30)/100,0) -> 197 | H30: P1 | I30: Residential Service | J30: Core | K30: /residential-fridge-repair/ | L30: EXISTING PAGE | M30: Secondary | N30: No - new find
A31: 30 | B31: ice machine repair | C31: Commercial | D31: 210 | E31: 6 | F31: 4.16 | G31: =ROUND(D31*(100-E31)/100,0) -> 197 | H31: P1 | I31: Ice Machine | J31: Core | K31: /ice-machine-repair/ | L31: NEW PAGE | M31: Secondary | N31: Yes | O31: /ice-machine-repair/
